Workbook
Name খাত: '[1]drop down'!$B$2:$B$5
Name সস: '[3]drop down'!$C$2:$C$8

Sheet অর্থ গ্রহণ
I1: অর্থ গ্রহণ ১৪৪৭/৪৮ হিজরী | M1: শাওয়াল | N1: জিলকাদ | O1: জিলহাজ | P1: মুহাররম | Q1: সফর | R1: রবিউল আঃ
I2: মোট অর্থ গ্রহণ | M2: =মাতবাখ!J2+মাদরাসা!J2 -> 2198085 | N2: =মাতবাখ!K2+মাদরাসা!K2 -> 902559 | O2: =মাতবাখ!L2+মাদরাসা!L2 -> 0 | P2: =মাতবাখ!M2+মাদরাসা!M2 -> 0 | Q2: =মাতবাখ!N2+মাদরাসা!N2 -> 0 | R2: =মাতবাখ!O2+মাদরাসা!O2 -> 0 | W2: মাদরাসা থেকে পাবো | X2: =0-K4 -> 5644
I3: =SUM(C:C) -> 3095000 | K3: বিদ্যমান | W3: বিভিন্ন স্থানে বকেয়া | X3: ='বাকির হিসাব'!$C$1 -> 233920
I4: মোট ব্যয় | K4: =I3-J8 -> -5644 | M4: রবিউস সানী | N4: জুমাদাল উলা | O4: জুমা:আখেরা | P4: রজব | Q4: শাবান | R4: রামাযান | W4: দফতরে বিদ্যমান | X4: =X3-X2 -> 228276
I5: মাতবাখ | J5: =SUM(মাতবাখ!H:H) -> 1919865 | M5: =মাতবাখ!J4+মাদরাসা!J4 -> 0 | N5: =মাতবাখ!K4+মাদরাসা!K4 -> 0 | O5: =মাতবাখ!L4+মাদরাসা!L4 -> 0 | P5: =মাতবাখ!M4+মাদরাসা!M4 -> 0 | Q5: =মাতবাখ!N4+মাদরাসা!N4 -> 0 | R5: =মাতবাখ!O4+মাদরাসা!O4 -> 0
I6: মাদরাসা | J6: =SUM(মাদরাসা!H:H) -> 1180779 | W6: বাসার করজ | X6: =SUM(#REF!) -> #REF!
A8: মাস | C8: পরিমাণ | D8: মন্তব্য | I8: মোট | J8: =SUM(J5:J7) -> 3100644
A9: শাওয়াল | B9: 9 | C9: 100000
A10: শাওয়াল | B10: 9 | C10: 300000
A11: শাওয়াল | B11: 9 | C11: 100000
A12: শাওয়াল | B12: 9 | C12: 100000
A13: শাওয়াল | B13: 11 | C13: 100000
A14: শাওয়াল | B14: 12 | C14: 100000
A15: শাওয়াল | B15: 15 | C15: 200000
A16: শাওয়াল | B16: 16 | C16: 100000
A17: শাওয়াল | B17: 17 | C17: 100000
A18: শাওয়াল | B18: 19 | C18: 100000
A19: শাওয়াল | B19: 20 | C19: 100000
A20: শাওয়াল | B20: 23 | C20: 145000
... A24: জিলকদ | B24: 7 | C24: 300000

Sheet মাতবাখ
C1: মাতবাখ ১৪৪৬/৪৭ হিজরী | J1: শাওয়াল | K1: জিলকাদ | L1: জিলহাজ | M1: মুহাররম | N1: সফর | O1: রবিউল আঃ | P1: =Q1-1 -> 46063 | Q1: 46064 | S1: সাগর | T1: সততা | U1: আল মদিনা | V1: লাকড়ি | W1: ডিম | X1: গ্যাস | Y1: জমিনের সবজী
J2: =SUMIFS(H:H,B:B,J1) -> 1207770 | K2: =SUMIFS($H$6:$H$1048576,B$6:B$1048576,K1) -> 712095 | L2: =SUMIFS($H$6:$H$1048576,B$6:B$1048576,L1) -> 0 | M2: =SUMIFS($H$6:$H$1048576,B$6:B$1048576,M1) -> 0 | N2: =SUMIFS($H$6:$H$1048576,B$6:B$1048576,N1) -> 0 | O2: =SUMIFS($H$6:$H$1048576,B$6:B$1048576,O1) -> 0 | S2: =SUMIFS(H:H,I:I,S1) -> 970140 | T2: =SUMIFS(H:H,I:I,T1) -> 0 | U2: =SUMIFS(H:H,I:I,U1) -> 0 | V2: =SUMIFS(H:H,I:I,V1) -> 0 | W2: =SUMIFS(H:H,I:I,W1) -> 52000 | X2: =SUMIFS(H:H,I:I,X1) -> 163300 | Y2: =SUMIFS(H:H,I:I,Y1) -> 45560
J3: রবিউল সানিঃ | K3: জুমাদাল উলা | L3: জুমা:আখেরা | M3: রজব | N3: শাবান | O3: রামাযান | R3: বাসার সামান | S3: =SUMIFS(H:H,D:D,R3) -> 0 | U3: মাখাবিজ | V3: =SUMIFS(H:H,I:I,U3) -> 0 | W3: গায়ের বাজার | X3: =SUMIFS(H:H,I:I,W3) -> 14020
J4: =SUMIFS($H$6:$H$1048576,B$6:B$1048576,J3) -> 0 | K4: =SUMIFS($H$6:$H$1048576,B$6:B$1048576,K3) -> 0 | L4: =SUMIFS($H$6:$H$1048576,B$6:B$1048576,L3) -> 0 | M4: =SUMIFS($H$6:$H$1048576,B$6:B$1048576,M3) -> 0 | N4: =SUMIFS($H$6:$H$1048576,B$6:B$1048576,N3) -> 0 | O4: =SUMIFS($H$6:$H$1048576,B$6:B$1048576,O3) -> 0
B5: মাস | D5: শাখা খাত | E5: বিবরণ | F5: পরিমাণ | G5: মূল্য | H5: মোট | I5: সরবরাহকারী | J5: রশিদ
A6: 1 | B6: শাওয়াল | C6: 2 | D6: কাঁচা বাজার | E6: পোলাউ চাল | F6: 50 | G6: =H6/F6 -> 156 | H6: 7800 | I6: সাগর
A7: 2 | B7: শাওয়াল | C7: 2 | D7: বড় বাজার | E7: মিনিকেট চাল | F7: 600 | G7: =H7/F7 -> 78 | H7: 46800 | I7: সাগর
A8: 3 | B8: শাওয়াল | C8: 3 | D8: কাঁচা বাজার | E8: সয়াবিন তেল | F8: 40 | G8: =H8/F8 -> 195 | H8: 7800 | I8: সাগর
A9: 4 | B9: শাওয়াল | C9: 3 | D9: কাঁচা বাজার | E9: খরচ | F9: 1 | G9: =H9/F9 -> 150 | H9: 150 | I9: সাগর
A10: 5 | B10: শাওয়াল | C10: 3 | D10: কাঁচা বাজার | E10: ধনিয়া পাতা | F10: 35 | G10: =H10/F10 -> 6 | H10: 210 | I10: সাগর
A11: 5 | B11: শাওয়াল | C11: 4 | D11: কাঁচা বাজার | E11: ময়দা | F11: 50 | G11: =H11/F11 -> 50 | H11: 2500 | I11: সাগর
A12: 6 | B12: শাওয়াল | C12: 4 | D12: কাঁচা বাজার | E12: আলু | F12: 130 | G12: =H12/F12 -> 17.692308 | H12: 2300 | I12: সাগর
A13: 7 | B13: শাওয়াল | C13: 4 | D13: কাঁচা বাজার | E13: আদা | F13: 5 | G13: =H13/F13 -> 150 | H13: 750 | I13: সাগর
A14: 8 | B14: শাওয়াল | C14: 4 | D14: কাঁচা বাজার | E14: খরচ | F14: 1 | G14: =H14/F14 -> 350 | H14: 350 | I14: সাগর
A15: 9 | B15: শাওয়াল | C15: 5 | D15: কাঁচা বাজার | E15: লাল ডিম | F15: 200 | G15: =H15/F15 -> 9 | H15: 1800 | I15: সাগর
A16: 10 | B16: শাওয়াল | C16: 5 | D16: কাঁচা বাজার | E16: ধনিয়া পাতা | F16: 1 | G16: =H16/F16 -> 80 | H16: 80 | I16: সাগর
A17: 11 | B17: শাওয়াল | C17: 5 | D17: কাঁচা বাজার | E17: খরচ | F17: 1 | G17: =H17/F17 -> 200 | H17: 200 | I17: সাগর
... A25: 19 | B25: শাওয়াল | C25: 7 | D25: কাঁচা বাজার | E25: খরচ | F25: 1 | G25: =H25/F25 -> 700 | H25: 700 | I25: সাগর
A26: 20 | B26: শাওয়াল | C26: 7 | D26: কাঁচা বাজার | E26: পোলাউ চাল | F26: 50 | G26: 50 | H26: 7200 | I26: সাগর
A27: 21 | B27: শাওয়াল | C27: 7 | D27: কাঁচা বাজার | E27: সয়াবিন তেল | F27: 40 | G27: =H27/F27 -> 191.75 | H27: 7670 | I27: সাগর
A28: 22 | B28: শাওয়াল | C28: 7 | D28: কাঁচা বাজার | E28: ঘি | F28: 2 | G28: =H28/F28 -> 1300 | H28: 2600 | I28: সাগর
A29: 23 | B29: শাওয়াল | C29: 7 | D29: কাঁচা বাজার | E29: দুধ | F29: 2 | G29: =H29/F29 -> 800 | H29: 1600 | I29: সাগর
A30: 24 | B30: শাওয়াল | C30: 7 | D30: কাঁচা বাজার | E30: দারচিনি | F30: 2 | G30: =H30/F30 -> 540 | H30: 1080 | I30: সাগর
A31: 25 | B31: শাওয়াল | C31: 7 | D31: কাঁচা বাজার | E31: আলু বোখারা | F31: 2 | G31: =H31/F31 -> 1250 | H31: 2500 | I31: সাগর
A32: 26 | B32: শাওয়াল | C32: 7 | D32: কাঁচা বাজার | E32: সরিষার তেল | F32: 17 | G32: =H32/F32 -> 105.88235 | H32: 1800 | I32: সাগর
A33: 27 | B33: শাওয়াল | C33: 8 | D33: কাঁচা বাজার | E33: মুরগী | F33: 61 | G33: =H33/F33 -> 374.91803 | H33: 22870 | I33: সাগর
A34: 28 | B34: শাওয়াল | C34: 8 | D34: কাঁচা বাজার | E34: আলু | F34: 130 | G34: =H34/F34 -> 16.923077 | H34: 2200 | I34: সাগর
A35: 29 | B35: শাওয়াল | C35: 8 | D35: কাঁচা বাজার | E35: পেয়াজ | F35: 40 | G35: =H35/F35 -> 37 | H35: 1480 | I35: সাগর
A36: 30 | B36: শাওয়াল | C36: 8 | D36: কাঁচা বাজার | E36: আদা | F36: 20 | G36: =H36/F36 -> 120 | H36: 2400 | I36: সাগর
A37: 31 | B37: শাওয়াল | C37: 8 | D37: কাঁচা বাজার | E37: রসুন | F37: 20 | G37: =H37/F37 -> 170 | H37: 3400 | I37: সাগর
A38: 32 | B38: শাওয়াল | C38: 8 | D38: কাঁচা বাজার | E38: খরচ | F38: 1 | G38: =H38/F38 -> 700 | H38: 700 | I38: সাগর
A39: 34 | B39: শাওয়াল | C39: 9 | D39: কাঁচা বাজার | E39: পেপে | F39: 185 | G39: =H39/F39 -> 25.405405 | H39: 4700
A40: 35 | B40: শাওয়াল | C40: 9 | D40: কাঁচা বাজার | E40: ভাড়া | F40: 1 | G40: =H40/F40 -> 500 | H40: 500
A41: 37 | B41: শাওয়াল | C41: 9 | D41: কাঁচা বাজার | E41: ডিম | F41: 500 | G41: =H41/F41 -> 9 | H41: 4500 | I41: সাগর
A42: 38 | B42: শাওয়াল | C42: 9 | D42: কাঁচা বাজার | E42: আলু | F42: 260 | G42: =H42/F42 -> 18.076923 | H42: 4700 | I42: সাগর
A43: 39 | B43: শাওয়াল | C43: 9 | D43: কাঁচা বাজার | E43: ধনিয়া পাতা | F43: 2 | G43: =H43/F43 -> 75 | H43: 150 | I43: সাগর
A44: 40 | B44: শাওয়াল | C44: 9 | D44: কাঁচা বাজার | E44: লাউ | F44: 80 | G44: =H44/F44 -> 40 | H44: 3200 | I44: সাগর
A45: 41 | B45: শাওয়াল | C45: 9 | D45: কাঁচা বাজার | E45: খরচ | F45: 1 | G45: =H45/F45 -> 400 | H45: 400 | I45: সাগর
A46: 42 | B46: শাওয়াল | C46: 10 | D46: কাঁচা বাজার | E46: মুরগী | F46: 62 | G46: =H46/F46 -> 380 | H46: 23560 | I46: সাগর
A47: 43 | B47: শাওয়াল | C47: 10 | D47: কাঁচা বাজার | E47: ধনিয়া পাতা | F47: 2 | G47: =H47/F47 -> 75 | H47: 150 | I47: সাগর
...

Sheet মাদরাসা
B1: মাদরাসা ১৪৪৬/৪৭ হিজরী | J1: শাওয়াল | K1: জিলকাদ | L1: জিলহাজ | M1: মুহাররম | N1: সফর | O1: রবিউল আঃ
J2: =SUMIFS(H:H,B:B,J1) -> 990315 | K2: =SUMIFS($H$7:$H$1048576,B$7:B$1048576,K1) -> 190464 | L2: =SUMIFS($H$7:$H$1048576,B$7:B$1048576,L1) -> 0 | M2: =SUMIFS($H$7:$H$1048576,B$7:B$1048576,M1) -> 0 | N2: =SUMIFS($H$7:$H$1048576,B$7:B$1048576,N1) -> 0 | O2: =SUMIFS($H$7:$H$1048576,B$7:B$1048576,O1)+'[1]অন্যান্য খাত'!I2 -> 0
J3: রবিউস সানিঃ | K3: জুমাদাল উলা | L3: জুমা:আখেরা | M3: রজব | N3: শাবান | O3: রামাযান
J4: =SUMIFS($H$7:$H$1048576,B$7:B$1048576,J3)+'[1]অন্যান্য খাত'!J2 -> 0 | K4: =SUMIFS($H$7:$H$1048576,B$7:B$1048576,K3) -> 0 | L4: =SUMIFS($H$7:$H$1048576,B$7:B$1048576,L3) -> 0 | M4: =SUMIFS($H$7:$H$1048576,B$7:B$1048576,M3) -> 0 | N4: =SUMIFS($H$7:$H$1048576,B$7:B$1048576,N3) -> 0 | O4: =SUMIFS($H$7:$H$1048576,B$7:B$1048576,O3) -> 0
B6: মাস | D6: শাখা খাত | E6: বিবরণ | F6: পরিমাণ | G6: মূল্য | H6: মোট | I6: সরবরাহকারী | J6: রশীদ
A7: 1 | B7: শাওয়াল | C7: 4 | E7: জাওয়াল সঞ্চয় | F7: 1 | G7: 1000 | H7: =F7*G7 -> 1000
A8: 2 | B8: শাওয়াল | C8: 4 | D8: মকতবের নাস্তা | E8: বিস্কুট- চকলেট | F8: 1 | G8: 8552 | H8: =F8*G8 -> 8552
A9: 4 | B9: শাওয়াল | C9: 4 | E9: আশরাফাবাদ যাতায়াত | F9: 1 | G9: 200 | H9: =F9*G9 -> 200
B10: শাওয়াল | C10: 4 | E10: জাওয়াল সঞ্চয় | F10: 1 | G10: 1000 | H10: =F10*G10 -> 1000
A11: 5 | B11: শাওয়াল | C11: 4 | E11: বালিশ | F11: 2 | G11: 340 | H11: =F11*G11 -> 680
A12: 6 | B12: শাওয়াল | C12: 4 | E12: জায়নামাজ | F12: 2 | G12: 450 | H12: =F12*G12 -> 900
A13: 7 | B13: শাওয়াল | C13: 4 | E13: যাতায়াত | F13: 1 | G13: 140 | H13: =F13*G13 -> 140
A14: 8 | B14: শাওয়াল | C14: 4 | E14: সাদ | F14: 1 | G14: 680 | H14: =F14*G14 -> 680
A15: 9 | B15: শাওয়াল | C15: 4 | E15: খেজুর | F15: 30 | G15: 560 | H15: =F15*G15 -> 16800
A16: 10 | B16: শাওয়াল | C16: 4 | E16: রুহ আফজা | F16: 2.5 | G16: 5760 | H16: =F16*G16 -> 14400 | I16: সাগর
A17: 11 | B17: শাওয়াল | C17: 6 | E17: কাগজ | F17: 1 | G17: 1 | H17: 480 | I17: সাগর
A18: 12 | B18: শাওয়াল | C18: 4 | E18: সরিষা | F18: 1 | H18: 52000 | I18: সাগর
A19: 13 | B19: শাওয়াল | C19: 8 | E19: চানাচুর | F19: 1.5 | H19: 450
A20: 14 | B20: শাওয়াল | C20: 8 | E20: মুড়ি | F20: 2 | H20: 160
A21: 15 | B21: শাওয়াল | C21: 8 | E21: স্বাদমিশালী | F21: 8 | H21: 40
A22: 16 | B22: শাওয়াল | C22: 8 | E22: শসা | F22: 0.5 | H22: 10
A23: 17 | B23: শাওয়াল | C23: 8 | E23: লেবু | F23: 2 | H23: 40
A24: 18 | B24: শাওয়াল | C24: 8 | E24: ভাড়া | F24: 1 | H24: 50
A25: 19 | B25: শাওয়াল | C25: 9 | D25: মকতবের নাস্তা | E25: মক্তবের নাস্তা | F25: 1 | H25: 1880
A26: 20 | B26: শাওয়াল | C26: 9 | E26: আশরাফাবাদ যাতায়াত | F26: 1 | H26: 600
A27: 21 | B27: শাওয়াল | C27: 9 | E27: ফোম | F27: 20 | H27: 10600
A28: 24 | B28: শাওয়াল | C28: 9 | E28: বিছানার কভার আনার ভাড়া | F28: 1 | H28: 1200
A29: 25 | B29: শাওয়াল | C29: 9 | D29: বিদ্যুৎ ও বিদ্যুতিকা | E29: বিদুৎ মিস্ত্রি | F29: 1.5 | G29: 1000 | H29: =F29*G29 -> 1500
A30: 26 | B30: শাওয়াল | C30: 9 | E30: জাওয়াল সঞ্চয় | F30: 1 | G30: 1000 | H30: =F30*G30 -> 1000
A31: 27 | B31: শাওয়াল | C31: 9 | D31: বিদ্যুৎ ও বিদ্যুতিকা | E31: ডিজেল | F31: 25 | H31: 3400 | I31: সাগর
A32: 28 | B32: শাওয়াল | C32: 10 | D32: মকতবের নাস্তা | E32: মক্তবের নাস্তা | F32: 1 | H32: 9600
A33: 29 | B33: শাওয়াল | C33: 10 | E33: ফ্রিজ মেরামত | H33: 3000
A34: 30 | B34: শাওয়াল | C34: 10 | D34: হুযূরের ব্যক্তিগত | E34: মালিবাগ যাতায়াত | F34: 1 | G34: 1 | H34: 5000
A35: 31 | B35: শাওয়াল | C35: 10 | D35: হুযূরের ব্যক্তিগত | E35: বাংলাবাজার যাতায়াত | F35: 1 | H35: 5000
A36: 32 | B36: শাওয়াল | C36: 10 | E36: ফেবিকল আঠা | F36: 1 | H36: 440 | I36: সাগর
A37: 33 | B37: শাওয়াল | C37: 10 | E37: কয়েল+লাইটার | F37: 1 | H37: 90 | I37: সাগর
A38: 34 | B38: শাওয়াল | C38: 10 | D38: বিদ্যুৎ ও বিদ্যুতিকা | E38: ডিজেল | F38: 25 | H38: 3400 | I38: সাগর
A39: 32 | B39: শাওয়াল | C39: 11 | E39: মাপযন্ত্র মেরামত | F39: 2 | H39: 1300
A40: 33 | B40: শাওয়াল | C40: 11 | D40: বিদ্যুৎ ও বিদ্যুতিকা | E40: পাখা মেরামত | H40: 200
A41: 34 | B41: শাওয়াল | C41: 11 | E41: কুতুবখানার হুজুরের বেন্ডর | F41: 1 | H41: 400
...

Sheet বাকির হিসাব
B1: মোট বকেয়া | C1: =SUM(H2:H9) -> 233920 | F1: গ্রহণ | G1: প্রদান | H1: বকেয়া
E2: সাগর | F2: =মাতবাখ!S2+মাদরাসা!U1 -> 970140 | G2: =SUMIFS(C$11:C$1048576,D$11:D$1048576,E2) -> 810000 | H2: =F2-G2 -> 160140
E3: আল মদিনা | F3: =মাতবাখ!T2+মাদরাসা!U2 -> 0 | G3: =SUMIFS(C$11:C$1048576,D$11:D$1048576,E3) -> 16080 | H3: =F3-G3 -> -16080
E4: মামুন | F4: =মাতবাখ!U2+মাদরাসা!U2 -> 0 | G4: =SUMIFS(C$11:C$1048576,D$11:D$1048576,E4) -> 0 | H4: =F4-G4 -> 0
E5: গ্যাস | F5: =SUMIFS(মাতবাখ!H:H,মাতবাখ!I:I,E5) -> 163300 | G5: =SUMIFS(C$11:C$1048576,D$11:D$1048576,E5) -> 100000 | H5: =F5-G5 -> 63300
E6: ডিম | F6: =SUMIFS(মাতবাখ!H:H,মাতবাখ!I:I,E6) -> 52000 | G6: =SUMIFS(C$11:C$1048576,D$11:D$1048576,E6) -> 26000 | H6: =F6-G6 -> 26000
E7: বেলাল | F7: =SUMIFS(মাতবাখ!H:H,মাতবাখ!I:I,E7)+মাদরাসা!U4 -> 0 | G7: =SUMIFS(C$11:C$1048576,D$11:D$1048576,E7) -> 0 | H7: =F7-G7 -> 0
E8: লাকড়ি | F8: =SUMIFS(মাতবাখ!H:H,মাতবাখ!I:I,E8)+মাদরাসা!U5 -> 0 | G8: =SUMIFS(C$11:C$1048576,D$11:D$1048576,E8) -> 0 | H8: =F8-G8 -> 0
E9: জমিনের সবজী | F9: =SUMIFS(মাতবাখ!H:H,মাতবাখ!I:I,E9) -> 45560 | G9: =SUMIFS(C$11:C$1048576,D$11:D$1048576,E9) -> 45000 | H9: =F9-G9 -> 560
B10: তারিখ | C10: পরিমাণ | D10: স্থান | E10: রশিদ
A11: 1 | B11: 9/10/1446 | C11: 100000 | D11: সাগর
A12: 2 | B12: 9/10/1446 | C12: 300000 | D12: সাগর
A13: 3 | B13: 46124 | C13: 150000 | D13: সাগর
A14: 4 | B14: 46125 | C14: 45000 | D14: জমিনের সবজী
A15: 5 | B15: 46126 | C15: 26000 | D15: ডিম
A16: 6 | B16: 46127 | C16: 110000 | D16: সাগর
A17: 7 | B17: 07/11/1446 | C17: 9720 | D17: আল মদিনা
A18: 8 | B18: 10/11/1446 | C18: 100000 | D18: গ্যাস
A19: 9 | B19: 18/11/1446 | C19: 50000 | D19: সাগর
A20: 10 | B20: 03/12/1446 | C20: 100000 | D20: সাগর
A21: 11 | B21: 07/12/1446 | C21: 6360 | D21: আল মদিনা
A22: 168
A23: 169
A24: 170
A25: 171
A26: 172
A27: 173
A28: 174
A29: 175
A30: 176
A31: 177
A32: 178
A33: 179
... A60: 206

Sheet ড্যাশবোর্ড
B2: মাতবাখ , মাদরাসা | I2: তামিরাত | Q2: মোট
B5: মোট অর্থ গ্রহণ | E5: =SUM('অর্থ গ্রহণ'!I3:$J$3) -> 3095000 | I5: মোট অর্থ গ্রহণ | L5: =SUM('[2]অর্থ গ্রহন'!$F$4:$G$4) -> 400000 | Q5: অর্থ গ্রহণ | S5: =SUM(E5+L5) -> 3495000
B7: মাতবাখ বাবদ মোট খরচ | E7: =SUM('অর্থ গ্রহণ'!$J$5) -> 1919865 | I7: মোট ব্যয় | L7: =SUM('[2]অর্থ গ্রহন'!$F$6:$G$6) -> 505173 | Q7: মোট ব্যয় | S7: =SUM(E10+L7) -> 3605817
B8: মাদরাসা বাবদ মোট খরচ | E8: =SUM('অর্থ গ্রহণ'!$J$6) -> 1180779 | I8: মোট বকেয়া/বিদ্যমান | L8: =SUM('[2]অর্থ গ্রহন'!$I$6:$J$6) -> -105173
Q9: মোট বিদ্যমান | S9: =SUM(E22+L8) -> 123103
B10: সর্বমোট খরচ | E10: =SUM('অর্থ গ্রহণ'!$J$8) -> 3100644 | I10: নগদ খরচ | L10: =SUM('[2]অর্থ গ্রহন'!$S$2:$T$2) -> 136375
B12: বিদ্যমান | E12: =SUM('অর্থ গ্রহণ'!K4:L5) -> -5644 | I12: বকেয়া আদায় | L12: =SUM('[2]অর্থ গ্রহন'!$S$4:$T$4) -> 100000
B14: মাতবাখ, মাদরাসা মোট বকেয়া | E14: =SUM('বাকির হিসাব'!$C$1) -> 233920 | I14: মোট আদায়কৃত অর্থ | L14: =SUM(L10,L12) -> 236375
I16: বকেয়া বিদ্যমান | L16: =SUM([2]বকেয়া!$K$1) -> 268798
B17: হুজুরের ব্যক্তিগত খরচ | E17: =SUM(মাদরাসা!$R$5) -> 0
B18: খেদমতে খালক | E18: =SUM(মাদরাসা!$R$2) -> 0 | I18: জমা থেকে বিদ্যমান | L18: =L5-L14 -> 163625
B19: বাসার করয | E19: =SUM(#REF!) -> #REF!
B20: মোট | E20: =SUM(E17:$F$19) -> #REF!
B22: দফতরে বিদ্যমান | E22: =SUM('অর্থ গ্রহণ'!X4:X5) -> 228276
