Workbook

Sheet অর্থ গ্রহন
G1: তামীরাত - ১৪৪৬/৪৭ হিজরী | P1: মাদরাসা থেকে পাবো | Q1: =-I6 -> 105173 | S1: নগদ খরচ
L2: দস্তরখান ভবন | N2: =SUM(খরচ!N2) -> 78205 | P2: বিভিন্ন স্থানে বকেয়া | Q2: =SUM(বকেয়া!$K$1) -> 268798 | S2: =SUM(খরচ!AA3) -> 136375
F3: মোট অর্থ গ্রহণ | L3: আবাসিক ভবন | N3: =SUM(খরচ!N3) -> 22594 | P3: দফতরে বিদ্যমান | Q3: =Q2-Q1 -> 163625 | S3: বকেয়া আদায়
F4: =SUM(D:D) -> 400000 | L4: মক্তব | N4: =SUM(খরচ!N4) -> 245413 | S4: =SUM(বকেয়া!C11:C230) -> 100000
F5: মোট ব্যয় | I5: বকেয়া/বিদ্যমান
B6: মাস | C6: তারীখ | D6: পরিমাণ | E6: মন্তব্য | F6: =SUM(খরচ!I2) -> 505173 | I6: =F4-F6 -> -105173
B7: যিলকাদ | C7: 46138 | D7: 100000 | E7: যিম্মাদার হুজুর
B8: যিলকাদ | C8: 46139 | D8: 300000 | E8: যিম্মাদার হুজুর
B9: শাওয়াল
B10: জিলকাদ
B11: জিলকাদ
B12: জিলকাদ
B13: জিলকাদ
B14: জিলকাদ
B15: জিলকাদ
B16: জিলহাজ
B17: জিলহাজ
B18: মুহাররম
B19: মুহাররম
B20: মুহাররম
... B32: রামযান

Sheet খরচ
S1: মোট হিসাব | T1: বাকি | U1: মোট হিসাব | V1: বাকি | W1: মোট হিসাব | X1: বাকি | Y1: মোট হিসাব | Z1: বাকি | AA1: নগদ
H2: মোট | I2: =SUM(H:H) -> 505173 | M2: দস্তরখান ভবন | N2: =SUMIFS(H:H,C:C,M2) -> 78205 | S2: আনোয়ার | T2: আনোয়ার | U2: কামাল সিমেন্ট | V2: কামাল সিমেন্ট | W2: ঊষা স্যানেটারি | X2: ঊষা স্যানেটারি | Y2: মা হার্ডওয়ার | Z2: মা হার্ডওয়ার
D3: তামীরাত - ১৪৪৭/৪৮ হিজরী | M3: আবাসিক ভবন | N3: =SUMIFS(H:H,C:C,M3) -> 22594 | S3: =SUMIFS(H:H,J:J,S2) -> 98072 | T3: =SUMIFS(I:I,J:J,T2) -> 0 | U3: =SUMIFS(H:H,J:J,U2) -> 7280 | V3: =SUMIFS(I:I,J:J,V2) -> 0 | W3: =SUMIFS(H:H,J:J,W2) -> 0 | X3: =SUMIFS(I:I,J:J,X2) -> 0 | Y3: =SUMIFS(H:H,J:J,Y2) -> 0 | Z3: =SUMIFS(I:I,J:J,Z2) -> 0 | AA3: =SUMIFS(H:H,J:J,AA1) -> 136375
A4: মাস | B4: তারিখ | C4: খাত | D4: বিবরণ | E4: পরিমাণ | F4: মাপ | G4: মূল্য | H4: খরচ | I4: বাকি | J4: সরবরাহকারি | K4: রশিদ নং | L4: মাধ্যম | M4: মক্তব | N4: =SUMIFS(H:H,C:C,M4) -> 245413 | S4: মোট হিসাব | T4: বাকি | U4: মোট হিসাব | V4: বাকি | W4: মোট হিসাব | X4: বাকি | Y4: মোট হিসাব | Z4: বাকি
A5: রামাযান | C5: মক্তব | D5: সিমেন্ট | E5: 14 | G5: 505 | H5: 7070 | J5: কামাল সিমেন্ট | S5: বিশাল থাই | T5: বিশাল থাই | U5: বন্ধু ট্রেডার্স | V5: বন্ধু ট্রেডার্স | W5: বেলাল আলীপুর | X5: বেলাল আলীপুর | Y5: কাঠ মিস্ত্রি | Z5: কাঠ মিস্ত্রি
A6: রামাযান | D6: ভাড়া | E6: 1 | H6: 210 | J6: কামাল সিমেন্ট | S6: =SUMIFS(H:H,J:J,S5) -> 0 | T6: =SUMIFS(I:I,J:J,T5) -> 0 | U6: =SUMIFS(H:H,J:J,U5) -> 138970 | V6: =SUMIFS(I:I,J:J,V5) -> 0 | W6: =SUMIFS(H:H,J:J,W5) -> 72476 | X6: =SUMIFS(I:I,J:J,X5) -> 0 | Y6: =SUMIFS(H:H,J:J,Y5) -> 52000 | Z6: =SUMIFS(I:I,J:J,Z5) -> 0
A7: রামাযান | C7: মক্তব | D7: মক্তব এবং বিদুতিকার টিন+এঙ্গেল | H7: 32381 | J7: আনোয়ার
A8: রামাযান | D8: মিস্ত্রি খরচ | H8: 11100 | J8: আনোয়ার
A9: শাওয়াল | B9: 46111 | D9: ৫” টলির চাকা | E9: 4 | G9: 5200 | H9: 5200 | J9: আনোয়ার
A10: শাওয়াল | B10: 46111 | D10: ৪” টলির চাকা | E10: 8 | G10: 4350 | H10: 8700 | J10: আনোয়ার
A11: শাওয়াল | B11: 46111 | D11: ফম ডিক্স | E11: 2 | G11: 45 | H11: 90 | J11: আনোয়ার
A12: শাওয়াল | B12: 46111 | D12: ওয়েল্ডিং রং | E12: 10 | G12: 20 | H12: 200 | J12: আনোয়ার
A13: শাওয়াল | B13: 46111 | D13: মিস্ত্রি | E13: 1 | H13: 1200 | J13: আনোয়ার
A14: শাওয়াল | B14: 46111 | D14: সহকারী | E14: 1 | H14: 900 | J14: আনোয়ার
A15: শাওয়াল | B15: 46120 | C15: মক্তব | D15: মক্তবের সুন্দুকের বোর্ড | H15: 19300 | J15: বন্ধু ট্রেডার্স | K15: 31
A16: শাওয়াল | B16: 46120 | C16: মক্তব | D16: মক্তবের সুন্দুকের বোর্ড | H16: 2700 | J16: বন্ধু ট্রেডার্স | K16: 31
A17: শাওয়াল | B17: 46120 | C17: মক্তব | D17: মক্তবের সুন্দুক | H17: 112550 | J17: বন্ধু ট্রেডার্স | K17: 53
A18: শাওয়াল | B18: 46120 | D18: বিভিন্ন সামান | H18: 9708 | J18: বেলাল আলীপুর | K18: 37
A19: শাওয়াল | B19: 46120 | D19: বিভিন্ন সামান | H19: 5460 | J19: বেলাল আলীপুর | K19: 38
A20: শাওয়াল | B20: 46120 | D20: বিভিন্ন সামান | H20: 15394 | J20: বেলাল আলীপুর | K20: 39
A21: শাওয়াল | B21: 46120 | D21: বিভিন্ন সামান | H21: 6660 | J21: বেলাল আলীপুর | K21: 40
A22: শাওয়াল | B22: 46120 | D22: বিভিন্ন সামান | H22: 3729 | J22: বেলাল আলীপুর | K22: 41
A23: শাওয়াল | B23: 46120 | D23: বিভিন্ন সামান | H23: 18280 | J23: বেলাল আলীপুর | K23: 42
A24: শাওয়াল | B24: 46120 | C24: দস্তরখান ভবন | D24: বেসিন | H24: 37000 | J24: নগদ | K24: 21 | L24: জাহিদ
A25: শাওয়াল | B25: 46120 | C25: দস্তরখান ভবন | D25: বেসিন | H25: 3140 | J25: নগদ | K25: 22 | L25: জাহিদ
A26: শাওয়াল | B26: 46120 | C26: দস্তরখান ভবন | D26: বেসিন | H26: 8530 | J26: নগদ | K26: 23 | L26: জাহিদ
A27: শাওয়াল | B27: 46120 | C27: দস্তরখান ভবন | D27: বেসিন | H27: 4000 | J27: নগদ | K27: 24 | L27: জাহিদ
A28: শাওয়াল | B28: 46120 | C28: দস্তরখান ভবন | D28: ভাড়া | E28: 1 | H28: 1470 | J28: নগদ | L28: জাহিদ
A29: শাওয়াল | B29: 46120 | C29: দস্তরখান ভবন | D29: লেভার খরচ | E29: 1 | G29: 550 | H29: =E29*G29 -> 550 | J29: নগদ | L29: জাহিদ
A30: শাওয়াল | B30: 46120 | D30: জাওয়াল সঞ্চয় | E30: 1 | H30: 80 | J30: নগদ | L30: জাহিদ
A31: শাওয়াল | B31: 46120 | D31: শমিকদের ভাড়া | E31: 2 | H31: 100 | J31: নগদ | L31: জাহিদ
A32: শাওয়াল | B32: 46120 | C32: মক্তব | D32: সুপার ষ্টার পাখা | E32: 3 | G32: 3700 | H32: =E32*G32 -> 11100 | J32: নগদ | L32: সাদ
A33: শাওয়াল | B33: 46120 | C33: আবাসিক ভবন | D33: তার | E33: 1 | G33: 9500 | H33: =E33*G33 -> 9500 | J33: নগদ | L33: সাদ
A34: শাওয়াল | B34: 46121 | C34: আবাসিক ভবন | D34: বেসিনের সামান | E34: 1 | H34: 3514 | J34: আনোয়ার
A35: শাওয়াল | B35: 46121 | C35: আবাসিক ভবন | D35: তাক প্রস্তুত | G35: 5974 | H35: 2460 | J35: আনোয়ার
A36: শাওয়াল | B36: 46121 | C36: দস্তরখান ভবন | D36: বেসিনের মিস্ত্রি | E36: 1 | H36: 6300 | J36: আনোয়ার
A37: শাওয়াল | B37: 46124 | C37: আবাসিক ভবন | D37: টাইলস মিস্ত্রি | E37: 1 | G37: 700 | H37: =E37*G37 -> 700 | J37: নগদ | L37: আবুল মনসুর
A38: শাওয়াল | B38: 46124 | C38: দস্তরখান ভবন | D38: পাইপ মিস্ত্রি | H38: 1000 | J38: নগদ | L38: জাহিদ
A39: শাওয়াল | B39: 46124 | C39: মক্তব | D39: মক্তবের সুন্দুক | E39: 10 | G39: 5000 | H39: 50000 | J39: কাঠ মিস্ত্রি
A40: শাওয়াল | B40: 46124 | C40: আবাসিক ভবন | D40: বুক সেলফ | E40: 2 | G40: 1000 | H40: 2000 | J40: কাঠ মিস্ত্রি
...

Sheet বকেয়া
B1: বিভিন্ন স্থানে বকেয়া ও অর্থ পরিশোধের হিসাব | G1: মোট | H1: আদায় | I1: অনাদায় | J1: মোট অনাদায় | K1: =SUM(I2:I9) -> 268798
F2: আনোয়ার | G2: =খরচ!$S$3 -> 98072 | H2: =SUMIFS(C11:C226,D11:D226,F2) -> 50000 | I2: =G2-H2 -> 48072
F3: বিশাল থাই | G3: =খরচ!$S$6 -> 0 | H3: =SUMIFS(C:C,D:D,F3) -> 0 | I3: =G3-H3 -> 0
F4: কামাল সিমেন্ট | G4: =খরচ!$U$3 -> 7280 | H4: =SUMIFS(C:C,D:D,F4) -> 0 | I4: =G4-H4 -> 7280
F5: বন্ধু ট্রেডার্স | G5: =খরচ!$U$6 -> 138970 | H5: =SUMIFS(C:C,D:D,F5) -> 50000 | I5: =G5-H5 -> 88970
F6: ঊষা স্যানেটারি | G6: =খরচ!$W$3 -> 0 | H6: =SUMIFS(C:C,D:D,F6) -> 0 | I6: =G6-H6 -> 0
F7: বেলাল আলীপুর | G7: =খরচ!$W$6 -> 72476 | H7: =SUMIFS(C:C,D:D,F7) -> 0 | I7: =G7-H7 -> 72476
F8: মা হার্ডওয়ার | G8: =খরচ!$Y$3 -> 0 | H8: =SUMIFS(C:C,D:D,F8) -> 0 | I8: =G8-H8 -> 0
F9: কাঠ মিস্ত্রি | G9: =খরচ!$Y$6 -> 52000 | H9: =SUMIFS(C:C,D:D,F9) -> 0 | I9: =G9-H9 -> 52000
A10: 7 | B10: তারিখ | C10: পরিমাণ | D10: স্থান | E10: রশিদ
A11: 1 | B11: 46121 | C11: 50000 | D11: আনোয়ার | E11: 61
A12: 2 | B12: 46124 | C12: 50000 | D12: বন্ধু ট্রেডার্স | E12: 65
A13: 3
A14: 4
A15: 5
A16: 6
A17: 7
A18: 8
A19: 9
A20: 10
A21: 11
A22: 12
A23: 13
A24: 14
... A230: 220
